Workbook
Name CENTRO_DE_COSTO: '[1]C.COST'!$A$2:$B$35
Name CENTRO_DE_COSTO: '[1]C.COST'!$A$2:$B$35
Name CENTRO_DE_COSTO: 'C.COST'!$A$2:$B$35
Name Cod_Requi_01: PEDIDO!$B$2:$B$22
Name Cod_Requi_02: [2]PEDIDO!#REF!
Name Cod_Requi_02: PEDIDO!#REF!
Name CuadroBasicoGral: [2]PRODUCTO!$B$5:$D$3000
Name CuadroBasicoGral: PRODUCTO!$B$5:$D$3000
Name IMQ: '[3]1'!$E$2:$G$4546
Name listado: '[2]C.COST'!$J$2:$J$35
Name listado: 'C.COST'!$J$2:$J$35
Name ListadoDetalle2023: ListadoOficial2023[[#All],[DESCRIPICION]:[Unidad Medida]]

Sheet PEDIDO
B1: CODIGOS | C1: NOMBRE DEL PRODUCTO | D1: PRESENTACION | E1: CANTIDAD SOLICITADA | F1: CANTIDAD DESPACHADA | H1: FECHA/HORA | J1: 46219 | U1: No. | V1: Copia Elaborac Pedido | W1: reordenar | X1: Listado
A2: =ROW(B1) -> 1 | B2: 910100338 | C2: =IFERROR(INDEX(ListadoOficial2023[],MATCH(B2,ListadoOficial2023[[Codigo ]],0),2),"") -> PILA DE 1.5 VOLTIOS TIPO "AA" DE ALTA DURACION | D2: =IFERROR(INDEX(ListadoOficial2023[],MATCH(B2,ListadoOficial2023[[Codigo ]],0),5),"") -> UN | E2: 4 | F2: 0 | H2: CENTRO COSTO****: | J2: MEDICINA GENERAL | K2: =IFERROR(VLOOKUP(J2,'C.COST'!A2:B44,2,FALSE),"") -> 538214 | U2: 1 | V2: Licda. Delia Alvarez | Y2: DR. MARVIN ERNESTO HUEZO | Z2: U200
A3: =ROW(B2) -> 2 | B3: 910200085 | C3: =IFERROR(INDEX(ListadoOficial2023[],MATCH(B3,ListadoOficial2023[[Codigo ]],0),2),"") -> PAPEL DE BOBINA PARA CANAPE 16" DE ANCHO POR 525 MTS DE LARGO APROXIMADAMENTE | D3: =IFERROR(INDEX(ListadoOficial2023[],MATCH(B3,ListadoOficial2023[[Codigo ]],0),5),"") -> C/U | E3: 4 | F3: 4 | U3: 2 | V3: Zuleyma Choto de Morán | Y3: Licdo. CARLOS UMAÑA | Z3: U300
A4: =ROW(B3) -> 3 | B4: 130200063 | C4: =IFERROR(INDEX(ListadoOficial2023[],MATCH(B4,ListadoOficial2023[[Codigo ]],0),2),"") -> VALE DE CONSUMO. FORM.PROV.70003.,BLOCK | D4: =IFERROR(INDEX(ListadoOficial2023[],MATCH(B4,ListadoOficial2023[[Codigo ]],0),5),"") -> BLO | E4: 3 | F4: 0 | H4: SOLICITA****: | J4: Licda. Delia Alvarez | U4: 3 | V4: Lic. Atilio Gonzalez | Z4: U400
A5: =ROW(B4) -> 4 | B5: 910100375 | C5: =IFERROR(INDEX(ListadoOficial2023[],MATCH(B5,ListadoOficial2023[[Codigo ]],0),2),"") -> ROLLO DE TIRRO DE 3/4 DE PULGADA DE ANCHO. | D5: =IFERROR(INDEX(ListadoOficial2023[],MATCH(B5,ListadoOficial2023[[Codigo ]],0),5),"") -> ROL | E5: 2 | F5: 0 | U5: 4 | V5: Iluana Peblis Avendaño | Z5: U500
A6: 5 | B6: 910100305 | C6: =IFERROR(INDEX(ListadoOficial2023[],MATCH(B6,ListadoOficial2023[[Codigo ]],0),2),"") -> GRAPAS DE MEDIDA STANDARD | D6: =IFERROR(INDEX(ListadoOficial2023[],MATCH(B6,ListadoOficial2023[[Codigo ]],0),5),"") -> CA | E6: 2 | F6: 2 | H6: AUTORIZA****: | J6: Licdo. CARLOS UMAÑA | U6: 35 | V6: Licda. Xiomara Machuca | Z6: U700
A7: =ROW(B6) -> 6 | B7: U | C7: =IFERROR(INDEX(ListadoOficial2023[],MATCH(B7,ListadoOficial2023[[Codigo ]],0),2),"") -> ********************ULTIMA LINEA **************************** | D7: =IFERROR(INDEX(ListadoOficial2023[],MATCH(B7,ListadoOficial2023[[Codigo ]],0),5),"") -> 0 | H7: DOC No. | U7: 35 | V7: Licda. Jeannette de Calderón | Z7: U800
A8: =ROW(B7) -> 7 | C8: =IFERROR(INDEX(ListadoOficial2023[],MATCH(B8,ListadoOficial2023[[Codigo ]],0),2),"") | D8: =IFERROR(INDEX(ListadoOficial2023[],MATCH(B8,ListadoOficial2023[[Codigo ]],0),5),"") | H8: No. Correlt de Docum, | J8: 47-07-2026-Papel | U8: 7 | V8: Licda. Merlin Aparicio
A9: =ROW(B8) -> 8 | C9: =IFERROR(INDEX(ListadoOficial2023[],MATCH(B9,ListadoOficial2023[[Codigo ]],0),2),"") | D9: =IFERROR(INDEX(ListadoOficial2023[],MATCH(B9,ListadoOficial2023[[Codigo ]],0),5),"") | H9: Tipo Almacen | J9: U200 | U9: 8 | V9: Licda. Helen Massiel Martinez
A10: =ROW(B9) -> 9 | C10: =IFERROR(INDEX(ListadoOficial2023[],MATCH(B10,ListadoOficial2023[[Codigo ]],0),2),"") | D10: =IFERROR(INDEX(ListadoOficial2023[],MATCH(B10,ListadoOficial2023[[Codigo ]],0),5),"") | H10: ****** ESTOS CAMPOS SON OBLIGATORIOS DE LLENARLOS | U10: 9 | V10: Xiomara Gonzales
A11: =ROW(B10) -> 10 | C11: =IFERROR(INDEX(ListadoOficial2023[],MATCH(B11,ListadoOficial2023[[Codigo ]],0),2),"") | D11: =IFERROR(INDEX(ListadoOficial2023[],MATCH(B11,ListadoOficial2023[[Codigo ]],0),5),"") | U11: 10 | V11: Ing. Yohana Laug
A12: =ROW(B11) -> 11 | C12: =IFERROR(INDEX(ListadoOficial2023[],MATCH(B12,ListadoOficial2023[[Codigo ]],0),2),"") | D12: =IFERROR(INDEX(ListadoOficial2023[],MATCH(B12,ListadoOficial2023[[Codigo ]],0),5),"") | U12: 11 | V12: Licdo. Daniel Henríquez
A13: =ROW(B12) -> 12 | C13: =IFERROR(INDEX(ListadoOficial2023[],MATCH(B13,ListadoOficial2023[[Codigo ]],0),2),"") | D13: =IFERROR(INDEX(ListadoOficial2023[],MATCH(B13,ListadoOficial2023[[Codigo ]],0),5),"") | U13: 12 | V13: Tito Noé Soriano
A14: =ROW(B13) -> 13 | C14: =IFERROR(INDEX(ListadoOficial2023[],MATCH(B14,ListadoOficial2023[[Codigo ]],0),2),"") | D14: =IFERROR(INDEX(ListadoOficial2023[],MATCH(B14,ListadoOficial2023[[Codigo ]],0),5),"") | U14: 13 | V14: Dania Mejia
A15: =ROW(B14) -> 14 | C15: =IFERROR(INDEX(ListadoOficial2023[],MATCH(B15,ListadoOficial2023[[Codigo ]],0),2),"") | D15: =IFERROR(INDEX(ListadoOficial2023[],MATCH(B15,ListadoOficial2023[[Codigo ]],0),5),"") | U15: 14 | V15: Claudia Perez
A16: =ROW(B15) -> 15 | C16: =IFERROR(INDEX(ListadoOficial2023[],MATCH(B16,ListadoOficial2023[[Codigo ]],0),2),"") | D16: =IFERROR(INDEX(ListadoOficial2023[],MATCH(B16,ListadoOficial2023[[Codigo ]],0),5),"") | U16: 35 | V16: Debora Escobar
A17: =ROW(B16) -> 16 | C17: =IFERROR(INDEX(ListadoOficial2023[],MATCH(B17,ListadoOficial2023[[Codigo ]],0),2),"") | D17: =IFERROR(INDEX(ListadoOficial2023[],MATCH(B17,ListadoOficial2023[[Codigo ]],0),5),"") | U17: 16 | V17: Claudia Iris Torrento
A18: =ROW(B17) -> 17 | C18: =IFERROR(INDEX(ListadoOficial2023[],MATCH(B18,ListadoOficial2023[[Codigo ]],0),2),"") | D18: =IFERROR(INDEX(ListadoOficial2023[],MATCH(B18,ListadoOficial2023[[Codigo ]],0),5),"") | U18: 17 | V18: Licda. Elizabeth Lino
A19: =ROW(B18) -> 18 | C19: =IFERROR(INDEX(ListadoOficial2023[],MATCH(B19,ListadoOficial2023[[Codigo ]],0),2),"") | D19: =IFERROR(INDEX(ListadoOficial2023[],MATCH(B19,ListadoOficial2023[[Codigo ]],0),5),"") | U19: 18 | V19: Licda. Mercedes de Hidalgo
A20: 19 | C20: =IFERROR(INDEX(ListadoOficial2023[],MATCH(B20,ListadoOficial2023[[Codigo ]],0),2),"") | D20: =IFERROR(INDEX(ListadoOficial2023[],MATCH(B20,ListadoOficial2023[[Codigo ]],0),5),"") | U20: 19 | V20: Celina Martínez
A21: =ROW(B20) -> 20 | C21: =IFERROR(INDEX(ListadoOficial2023[],MATCH(B21,ListadoOficial2023[[Codigo ]],0),2),"") | D21: =IFERROR(INDEX(ListadoOficial2023[],MATCH(B21,ListadoOficial2023[[Codigo ]],0),5),"") | U21: 35 | V21: Licda. Mayra Acosta
A22: =ROW(B21) -> 21 | C22: =IFERROR(INDEX(ListadoOficial2023[],MATCH(B22,ListadoOficial2023[[Codigo ]],0),2),"") | D22: =IFERROR(INDEX(ListadoOficial2023[],MATCH(B22,ListadoOficial2023[[Codigo ]],0),5),"") | U22: 35 | V22: Licda. Iris Vivas
U23: 19 | V23: Licdo. Geovvani Torres
E24: 1 | U24: 20 | V24: Licda. Cristina Aguillón
U25: 21 | V25: Francisco Rivas
U26: 22 | V26: Dra. Blanca Fuentes De Ventura
U27: 23 | V27: Lic. Edwin Cáceres
U28: 24 | V28: Licda. kathia Portillo
U29: 25 | V29: Veronica Rivera
U30: 26 | V30: Licda. Marisol Ventura
U31: 27 | V31: Dr. Luis Alfonso Flores Ponce
U32: 28 | V32: Licda. Silvia Chevez
U33: 29 | V33: Dr. Ernesto Alexander Salazar
U34: 30 | V34: Licda. Sandra Carolina Calles

Sheet REQUISICION-IMPRESION
A1: INSTITUTO SALVADOREÑO DEL SEGURO SOCIAL | AE1: !!CODIGO ANTIGUO, VERIFICAR HOJA PRODUCTO!!
A2: REQUISICION INTERNA | AE2: ERROR
V3: ACTUALIZADO:ENERO2025
A4: 1 | C4: CENTRO DE ATENCION | L4: 2 | M4: FECHA | R4: 3 | S4: Correlativo No. | W4: =PEDIDO!J8 -> 47-07-2026-Papel
L5: DIA | N5: MES | P5: AÑO | R5: =PEDIDO!$J$2 -> MEDICINA GENERAL
A6: UNIDAD MEDICA SOYAPANGO | L6: =PEDIDO!J1 -> 46219
BM7: 3 | BN7: =COUNTIF(BM7:BM27," > 0") -> 0
BM8: =$Z$19
A9: 4 | P9: VALOR | U9: $ | BM9: =Z20 -> 0
BM10: =Z21 -> 0
A11: IDEM | C11: MOV | D11: ALMACEN | F11: DEPEND.DESTINATARIA | M11: LOTE Nº. | Q11: AÑO | U11: MES | W11: TOTAL CODIGOS | BM11: =Z22 -> 2
A12: (1) | C12: (2) | D12: (3-4) | F12: =PEDIDO!K2 -> 538214 | M12: (12-15) | Q12: (16-19) | U12: (20-21) | W12: (22-28) | BM12: =Z23
C13: 201 | D13: =PEDIDO!J9 -> U200 | W13: Despachada | Z13: NO Despachad | BM13: =Z24
Q14: =YEAR(L6) -> 2026 | U14: =MONTH(L6) -> 7 | X14: =IF(COUNTIF($Z$18:$Z$38,">0"),COUNTIF($Z$18:$Z$38,">0"),"") -> 2 | AA14: =IF(COUNTIF($Z$18:$Z$38,"=0"),COUNTIF($Z$18:$Z$38,"=0"),"") -> 3 | BM14: =Z25
F15: . | BM15: =Z26
A16: 5 | C16: 6 | E16: 7 | F16: NOMBRE DEL PRODUCTO | R16: 8 | S16: PRESEN- | V16: 9 | W16: CANTIDAD | Z16: 10 | AA16: CANTIDAD | BM16: =Z27
A17: Nº | C17: CODIGO | S17: TACION | W17: SOLICITADA | AA17: DESPACHADA | BM17: =Z28
A18: 1 | C18: =IF(PEDIDO!B2>0,PEDIDO!B2,"") -> 910100338 | E18: =IFERROR(INDEX(ListadoOficial2023[],MATCH(C18,ListadoOficial2023[[Codigo ]],0),2),"") -> PILA DE 1.5 VOLTIOS TIPO "AA" DE ALTA DURACION | R18: =IFERROR(INDEX(ListadoOficial2023[],MATCH(C18,ListadoOficial2023[[Codigo ]],0),5),"") -> UN | V18: =IF(PEDIDO!E2>0,PEDIDO!E2,"") -> 4 | Z18: =IF(PEDIDO!F2<>"",PEDIDO!F2,"") -> 0 | BM18: =Z29
A19: 2 | C19: =IF(PEDIDO!B3>0,PEDIDO!B3,"") -> 910200085 | E19: =IFERROR(INDEX(ListadoOficial2023[],MATCH(C19,ListadoOficial2023[[Codigo ]],0),2),"") -> PAPEL DE BOBINA PARA CANAPE 16" DE ANCHO POR 525 MTS DE LARGO APROXIMADAMENTE | R19: =IFERROR(INDEX(ListadoOficial2023[],MATCH(C19,ListadoOficial2023[[Codigo ]],0),5),"") -> C/U | V19: =IF(PEDIDO!E3>0,PEDIDO!E3,"") -> 4 | Z19: =IF(PEDIDO!F3<>"",PEDIDO!F3,"") -> 4 | BM19: =Z30
A20: 3 | C20: =IF(PEDIDO!B4>0,PEDIDO!B4,"") -> 130200063 | E20: =IFERROR(INDEX(ListadoOficial2023[],MATCH(C20,ListadoOficial2023[[Codigo ]],0),2),"") -> VALE DE CONSUMO. FORM.PROV.70003.,BLOCK | R20: =IFERROR(INDEX(ListadoOficial2023[],MATCH(C20,ListadoOficial2023[[Codigo ]],0),5),"") -> BLO | V20: =IF(PEDIDO!E4>0,PEDIDO!E4,"") -> 3 | Z20: =IF(PEDIDO!F4<>"",PEDIDO!F4,"") -> 0 | BM20: =Z31
A21: 4 | C21: =IF(PEDIDO!B5>0,PEDIDO!B5,"") -> 910100375 | E21: =IFERROR(INDEX(ListadoOficial2023[],MATCH(C21,ListadoOficial2023[[Codigo ]],0),2),"") -> ROLLO DE TIRRO DE 3/4 DE PULGADA DE ANCHO. | R21: =IFERROR(INDEX(ListadoOficial2023[],MATCH(C21,ListadoOficial2023[[Codigo ]],0),5),"") -> ROL | V21: =IF(PEDIDO!E5>0,PEDIDO!E5,"") -> 2 | Z21: =IF(PEDIDO!F5<>"",PEDIDO!F5,"") -> 0 | BM21: =Z32
A22: 5 | C22: =IF(PEDIDO!B6>0,PEDIDO!B6,"") -> 910100305 | E22: =IFERROR(INDEX(ListadoOficial2023[],MATCH(C22,ListadoOficial2023[[Codigo ]],0),2),"") -> GRAPAS DE MEDIDA STANDARD | R22: =IFERROR(INDEX(ListadoOficial2023[],MATCH(C22,ListadoOficial2023[[Codigo ]],0),5),"") -> CA | V22: =IF(PEDIDO!E6>0,PEDIDO!E6,"") -> 2 | Z22: =IF(PEDIDO!F6<>"",PEDIDO!F6,"") -> 2 | BM22: =Z33
A23: 6 | C23: =IF(PEDIDO!B7>0,PEDIDO!B7,"") -> U | E23: =IFERROR(INDEX(ListadoOficial2023[],MATCH(C23,ListadoOficial2023[[Codigo ]],0),2),"") -> ********************ULTIMA LINEA **************************** | R23: =IFERROR(INDEX(ListadoOficial2023[],MATCH(C23,ListadoOficial2023[[Codigo ]],0),5),"") -> 0 | V23: =IF(PEDIDO!E7>0,PEDIDO!E7,"") | Z23: =IF(PEDIDO!F7<>"",PEDIDO!F7,"") | BM23: =Z34
A24: 7 | C24: =IF(PEDIDO!B8>0,PEDIDO!B8,"") | E24: =IFERROR(INDEX(ListadoOficial2023[],MATCH(C24,ListadoOficial2023[[Codigo ]],0),2),"") | R24: =IFERROR(INDEX(ListadoOficial2023[],MATCH(C24,ListadoOficial2023[[Codigo ]],0),5),"") | V24: =IF(PEDIDO!E8>0,PEDIDO!E8,"") | Z24: =IF(PEDIDO!F8<>"",PEDIDO!F8,"") | BM24: =Z35
A25: 8 | C25: =IF(PEDIDO!B9>0,PEDIDO!B9,"") | E25: =IFERROR(INDEX(ListadoOficial2023[],MATCH(C25,ListadoOficial2023[[Codigo ]],0),2),"") | R25: =IFERROR(INDEX(ListadoOficial2023[],MATCH(C25,ListadoOficial2023[[Codigo ]],0),5),"") | V25: =IF(PEDIDO!E9>0,PEDIDO!E9,"") | Z25: =IF(PEDIDO!F9<>"",PEDIDO!F9,"") | BM25: =Z36
A26: 9 | C26: =IF(PEDIDO!B10>0,PEDIDO!B10,"") | E26: =IFERROR(INDEX(ListadoOficial2023[],MATCH(C26,ListadoOficial2023[[Codigo ]],0),2),"") | R26: =IFERROR(INDEX(ListadoOficial2023[],MATCH(C26,ListadoOficial2023[[Codigo ]],0),5),"") | V26: =IF(PEDIDO!E10>0,PEDIDO!E10,"") | Z26: =IF(PEDIDO!F10<>"",PEDIDO!F10,"") | BM26: =Z37
A27: 10 | C27: =IF(PEDIDO!B11>0,PEDIDO!B11,"") | E27: =IFERROR(INDEX(ListadoOficial2023[],MATCH(C27,ListadoOficial2023[[Codigo ]],0),2),"") | R27: =IFERROR(INDEX(ListadoOficial2023[],MATCH(C27,ListadoOficial2023[[Codigo ]],0),5),"") | V27: =IF(PEDIDO!E11>0,PEDIDO!E11,"") | Z27: =IF(PEDIDO!F11<>"",PEDIDO!F11,"") | BM27: =Z38
A28: 11 | C28: =IF(PEDIDO!B12>0,PEDIDO!B12,"") | E28: =IFERROR(INDEX(ListadoOficial2023[],MATCH(C28,ListadoOficial2023[[Codigo ]],0),2),"") | R28: =IFERROR(INDEX(ListadoOficial2023[],MATCH(C28,ListadoOficial2023[[Codigo ]],0),5),"") | V28: =IF(PEDIDO!E12>0,PEDIDO!E12,"") | Z28: =IF(PEDIDO!F12<>"",PEDIDO!F12,"")
A29: 12 | C29: =IF(PEDIDO!B13>0,PEDIDO!B13,"") | E29: =IFERROR(INDEX(ListadoOficial2023[],MATCH(C29,ListadoOficial2023[[Codigo ]],0),2),"") | R29: =IFERROR(INDEX(ListadoOficial2023[],MATCH(C29,ListadoOficial2023[[Codigo ]],0),5),"") | V29: =IF(PEDIDO!E13>0,PEDIDO!E13,"") | Z29: =IF(PEDIDO!F13<>"",PEDIDO!F13,"")
A30: 13 | C30: =IF(PEDIDO!B14>0,PEDIDO!B14,"") | E30: =IFERROR(INDEX(ListadoOficial2023[],MATCH(C30,ListadoOficial2023[[Codigo ]],0),2),"") | R30: =IFERROR(INDEX(ListadoOficial2023[],MATCH(C30,ListadoOficial2023[[Codigo ]],0),5),"") | V30: =IF(PEDIDO!E14>0,PEDIDO!E14,"") | Z30: =IF(PEDIDO!F14<>"",PEDIDO!F14,"")
A31: 14 | C31: =IF(PEDIDO!B15>0,PEDIDO!B15,"") | E31: =IFERROR(INDEX(ListadoOficial2023[],MATCH(C31,ListadoOficial2023[[Codigo ]],0),2),"") | R31: =IFERROR(INDEX(ListadoOficial2023[],MATCH(C31,ListadoOficial2023[[Codigo ]],0),5),"") | V31: =IF(PEDIDO!E15>0,PEDIDO!E15,"") | Z31: =IF(PEDIDO!F15<>"",PEDIDO!F15,"")
A32: 15 | C32: =IF(PEDIDO!B16>0,PEDIDO!B16,"") | E32: =IFERROR(INDEX(ListadoOficial2023[],MATCH(C32,ListadoOficial2023[[Codigo ]],0),2),"") | R32: =IFERROR(INDEX(ListadoOficial2023[],MATCH(C32,ListadoOficial2023[[Codigo ]],0),5),"") | V32: =IF(PEDIDO!E16>0,PEDIDO!E16,"") | Z32: =IF(PEDIDO!F16<>"",PEDIDO!F16,"")
A33: 16 | C33: =IF(PEDIDO!B17>0,PEDIDO!B17,"") | E33: =IFERROR(INDEX(ListadoOficial2023[],MATCH(C33,ListadoOficial2023[[Codigo ]],0),2),"") | R33: =IFERROR(INDEX(ListadoOficial2023[],MATCH(C33,ListadoOficial2023[[Codigo ]],0),5),"") | V33: =IF(PEDIDO!E17>0,PEDIDO!E17,"") | Z33: =IF(PEDIDO!F17<>"",PEDIDO!F17,"")
A34: 17 | C34: =IF(PEDIDO!B18>0,PEDIDO!B18,"") | E34: =IFERROR(INDEX(ListadoOficial2023[],MATCH(C34,ListadoOficial2023[[Codigo ]],0),2),"") | R34: =IFERROR(INDEX(ListadoOficial2023[],MATCH(C34,ListadoOficial2023[[Codigo ]],0),5),"") | V34: =IF(PEDIDO!E18>0,PEDIDO!E18,"") | Z34: =IF(PEDIDO!F18<>"",PEDIDO!F18,"")
A35: 18 | C35: =IF(PEDIDO!B19>0,PEDIDO!B19,"") | E35: =IFERROR(INDEX(ListadoOficial2023[],MATCH(C35,ListadoOficial2023[[Codigo ]],0),2),"") | R35: =IFERROR(INDEX(ListadoOficial2023[],MATCH(C35,ListadoOficial2023[[Codigo ]],0),5),"") | V35: =IF(PEDIDO!E19>0,PEDIDO!E19,"") | Z35: =IF(PEDIDO!F19<>"",PEDIDO!F19,"")
A36: 19 | C36: =IF(PEDIDO!B20>0,PEDIDO!B20,"") | E36: =IFERROR(INDEX(ListadoOficial2023[],MATCH(C36,ListadoOficial2023[[Codigo ]],0),2),"") | R36: =IFERROR(INDEX(ListadoOficial2023[],MATCH(C36,ListadoOficial2023[[Codigo ]],0),5),"") | V36: =IF(PEDIDO!E20>0,PEDIDO!E20,"") | Z36: =IF(PEDIDO!F20<>"",PEDIDO!F20,"")
A37: 20 | C37: =IF(PEDIDO!B21>0,PEDIDO!B21,"") | E37: =IFERROR(INDEX(ListadoOficial2023[],MATCH(C37,ListadoOficial2023[[Codigo ]],0),2),"") | R37: =IFERROR(INDEX(ListadoOficial2023[],MATCH(C37,ListadoOficial2023[[Codigo ]],0),5),"") | V37: =IF(PEDIDO!E21>0,PEDIDO!E21,"") | Z37: =IF(PEDIDO!F21<>"",PEDIDO!F21,"")
A38: 21 | C38: =IF(PEDIDO!B22>0,PEDIDO!B22,"") | E38: =IFERROR(INDEX(ListadoOficial2023[],MATCH(C38,ListadoOficial2023[[Codigo ]],0),2),"") | R38: =IFERROR(INDEX(ListadoOficial2023[],MATCH(C38,ListadoOficial2023[[Codigo ]],0),5),"") | V38: =IF(PEDIDO!E22>0,PEDIDO!E22,"") | Z38: =IF(PEDIDO!F22<>"",PEDIDO!F22,"")
E39: DOC. | G39: =PEDIDO!J7 -> 0
A41: SOLICITO | H41: AUTORIZO | S41: RECIBIO
...

Sheet PRODUCTO
A1: INSTITUTO SALVADOREÑO DEL SEGURO SOCIAL
A2: UNIDAD MEDICA SOYAPANGO
A3: BASE DATOS SOBRE CODIGO DE INSUMOS MEDICOS Y ARTICULOS GENERALES
A4: CODIGO ANTIGUO | B4: CODIGO ACTUAL | C4: DESCRIPCION | D4: PRESENTACION | E4: ALMACEN
B5: 2004002 | C5: ETER SULFURICO (ETER ETILICO) (C4 H10O) | D5: ML | E5: U500
B6: 2006005 | C6: ANTIESTREPTOLISINA "O" | D6: ML | E6: U500
B7: 2006024 | C7: PROTEINA "C" REACTIVA (PCR) | D7: C/U | E7: U500
B8: 2006025 | C8: FACTOR REUMATOIDE (LATEX R.A.) | D8: C/U | E8: U500
B9: 2006030 | C9: PRUEB. CUANT DET.REAGINA T. PALLIDUM | D9: C/U | E9: U500
B10: 2006031 | C10: REACTIVO D. SANGRE OCULTA EN HECES | D10: C/U | E10: U500
B11: 2006032 | C11: TIRAS REACTS DENSID. SUSTS QCAS ORINA | D11: TIRA | E11: U500
B12: 2006036 | C12: TIRAS REACTS DETER SUST QCAS EN ORINA | D12: PRUEBA | E12: U500
B13: 2006038 | C13: TIEMPO DE/TROMBOPLASTINA PARCIAL (TTP) | D13: PRUEBA | E13: U500
B14: 2006088 | C14: TIRA REACTIVA DETERM. GLUCOSA EN SANGRE | D14: TIRAS | E14: U500
B15: 2006132 | C15: PRUEBA RAP. S-UNIDAD B-GON.CORIONICA HUM | D15: TIRAS | E15: U500
B16: 2006133 | C16: PRUEBA RAP. CUALIT. ANTICUERPO ANTI VIH | D16: C/U | E16: U500
... B86: 2106025 | C86: ACEITE DE INMERSION BAJA VISCOSIDAD | D86: ML | E86: U500
A87: 3500000 | B87: 3500121 | C87: LAMINA CUBRE OBJETOS DE 22X22 | D87: C/U | E87: U500
A88: 3500001 | B88: 3500122 | C88: PIPETA PARA COAGULOMETRO TIPO CLOT 2. C/U | D88: C/U | E88: U500
A89: 3500002 | B89: 3500123 | C89: LAMINA PORTA OBJETO 3 X 1" EXTREMO ESMERILADO DE VIDRIO.C/U | D89: C/U | E89: U500
A90: 3500003 | B90: 3500124 | C90: LAMINA SELLADORA PARA MICROHEMATOCRITO. C/U | D90: C/U | E90: U500
A91: 3500004 | B91: 3500125 | C91: LAMINILLA CUBRE OBJETOS 22 X 50 mm DE VIDRIO. ONZA | D91: ONZA | E91: U500
A92: 3500005 | B92: 3500126 | C92: LANCETA DESCARTABLE PARA USO PEDIATRICO.C/U | D92: C/U | E92: U500
A93: 3500006 | B93: 3500127 | C93: LANCETA DESCARTABLE PUNTO MEDIO. C/U | D93: C/U | E93: U500
A94: 3500007 | B94: 3500128 | C94: PAPEL FILTRO CORRIENTE # 2. PLIEGO | D94: PLIEGO | E94: U500
A95: 3500008 | B95: 3500129 | C95: PAPEL PARAFINA DE 4" ANCHO, 125" DE LARGO. APROXIMADAMENTE. ROLLO | D95: ROLLO | E95: U500
A96: 3500009 | B96: 3500130 | C96: CAJA PETRI DESCARTABLE (100 X 15 mm APROXIMADAMENTE) DE 1 COMPARTIMIENTO, ESTERIL. C/U | D96: C/U | E96: U500
A97: 3500010 | B97: 3500131 | C97: GOTERO PLASTICO 70 mm APROX. C/BULBO | D97: C/U | E97: U500
A98: 3500011 | B98: 3500132 | C98: PUNTA PLASTICA DESCARTABLE PARA FIBROSISTEMA. C/U | D98: C/U | E98: U500
B99: 3500012 | C99: PUNTA PLASTICA DE 1 mL (1000µL ) PARA USAR CON PIPETA TIPO OXFORD O SIMILAR. C/U | D99: C/U | E99: U500
A100: 3500013 | B100: 3500133 | C100: PUNTA PLASTICA DE 0.5 mL (500 µL ) PARA USAR CON PIPETA TIPO OXFORD O SIMILAR. C/U | D100: C/U | E100: U500
A101: 3500014 | B101: 3500134 | C101: PUNTA PLASTICA DE 0.1 mL (100 µL ) PARA USAR CON PIPETA TIPO OXFORD O SIMILAR. C/U | D101: C/U | E101: U500
A102: 3500015 | B102: 3500135 | C102: TUBO CAPILAR HEPARINIZADO PARA MICROHEMATOCRITO 1.3 X 1.5 X 75 mm. C/U | D102: C/U | E102: U500
A103: 3500016 | B103: 3500136 | C103: TUBO CAPILAR NO HEPARINIZADO PARA MICROHEMATOCRITO 1.3 X 1.5 X 75 mm. C/U | D103: C/U | E103: U500
A104: 3500017 | B104: 3500137 | C104: PUNTA PLASTICA DE 2 - 100 µl PARA USAR CON PIPETA TIPO BRAND (TRANSFERPETTE) O SIMILAR. C/U | D104: C/U | E104: U500
B105: 3500018 | C105: PUNTA PLASTICA DE 101 - 1000 µl PARA USAR CON PIPETA TIPO BRAND (TRANSFERPETTE) O SIMILAR. C/U | D105: C/U | E105: U500
A106: 3500019 | B106: 3500138 | C106: CUBETA DE PLASTICO DESCARTABLE, TRANSPARENTE, CON SU RESPECTIVO MAGNETO, PARA COAGULOMETRO DE MARCA Y MODELO DE EQUIPO INSTITUCIONAL. CUBETA. | D106: CUBETA | E106: U500
A107: 2320030 | B107: 3500020 | C107: CAJA PLASTICA PARA RECOLECCION DE HECES, COLOR Y TAPADERA BLANCA DE ROSCA, DIAMETRO 4.5 cm (APROXIMADAMENTE). C/U | D107: C/U | E107: U500
A108: 3500021 | B108: 3500139 | C108: FILTRO PARA DESMINERALIZADOR DE AGUA, TIPO DEEMINIZER O SIMILAR. C/U | D108: C/U | E108: U500
A109: 3500022 | B109: 3500140 | C109: CAJA PETRI DESCARTABLE (100 X 15 mm APROXIMADAMENTE) DE 2 COMPARTIMIENTOS, ESTERIL. C/U | D109: C/U | E109: U500
...

Sheet C.COST
A1: UNIDAD PRESUPUESTARIA, LINEA Y SUBLINE DE TRABAJO Y CENTRO DE COSTO | B1: CENTRO DE COSTO | C1: ELABORA PEDIDO | D1: JEFE INMEDIATO | E1: Autoriza | G1: No. | H1: Copia Elaborac Pedido | I1: reordenar | J1: Listado
A2: DIRECCION | B2: 538001 | C2: Luz Adela Larreynaga | D2: DRA. GRICELDA DE GOMEZ | E2: DRA. GRICELDA DE GOMEZ | G2: 1 | H2: =C2 -> Luz Adela Larreynaga | I2: =IF(H2=0,MAX($G$2:$G$35)+1,G2) -> 1 | J2: =IFERROR(VLOOKUP(SMALL($I$2:$I$35,G2),$G$2:$H$35,2,FALSE),"X") -> Luz Adela Larreynaga
A3: ADMINISTRACION | B3: 538101 | C3: Zuleyma Choco | D3: LICDO. MARIANO MERLOS | E3: LIC. MARIANO MERLOS | G3: 2 | H3: =C3 -> Zuleyma Choco | I3: =IF(H3=0,MAX($G$2:$G$35)+1,G3) -> 2 | J3: =IFERROR(VLOOKUP(SMALL($I$2:$I$35,G3),$G$2:$H$35,2,FALSE),"X") -> Zuleyma Choco
A4: SERVICIOS GENERALES | B4: 538102 | C4: Lic. Atilio Gonzalez | D4: Lic. Atilio Gonzalez | G4: 3 | H4: =C4 -> Lic. Atilio Gonzalez | I4: =IF(H4=0,MAX($G$2:$G$35)+1,G4) -> 3 | J4: =IFERROR(VLOOKUP(SMALL($I$2:$I$35,G4),$G$2:$H$35,2,FALSE),"X") -> Lic. Atilio Gonzalez
A5: ALMACEN | B5: 538103 | C5: Iluana Peblis Avendaño | D5: Francisco Alfredo Rivas | G5: 4 | H5: =C5 -> Iluana Peblis Avendaño | I5: =IF(H5=0,MAX($G$2:$G$35)+1,G5) -> 4 | J5: =IFERROR(VLOOKUP(SMALL($I$2:$I$35,G5),$G$2:$H$35,2,FALSE),"X") -> Iluana Peblis Avendaño
A6: LAVANDERIA | B6: 538104 | G6: 5 | H6: =C6 -> 0 | I6: =IF(H6=0,MAX($G$2:$G$35)+1,G6) -> 35 | J6: =IFERROR(VLOOKUP(SMALL($I$2:$I$35,G6),$G$2:$H$35,2,FALSE),"X") -> Licda. Xiomara Machuca
A7: TRANSPORTE | B7: 538105 | G7: 6 | H7: =C7 -> 0 | I7: =IF(H7=0,MAX($G$2:$G$35)+1,G7) -> 35 | J7: =IFERROR(VLOOKUP(SMALL($I$2:$I$35,G7),$G$2:$H$35,2,FALSE),"X") -> Licda. Jeannette de Calderón
A8: ADMISION Y REGISTROS MEDICOS | B8: 538107 | C8: Licda. Xiomara Machuca | G8: 7 | H8: =C8 -> Licda. Xiomara Machuca | I8: =IF(H8=0,MAX($G$2:$G$35)+1,G8) -> 7 | J8: =IFERROR(VLOOKUP(SMALL($I$2:$I$35,G8),$G$2:$H$35,2,FALSE),"X") -> Merlin Aparicio
A9: RADIOLOGIA E IMÁGENES | B9: 538A04 | C9: Licda. Jeannette de Calderón | D9: Licda. Jeannette de Calderón | G9: 8 | H9: =C9 -> Licda. Jeannette de Calderón | I9: =IF(H9=0,MAX($G$2:$G$35)+1,G9) -> 8 | J9: =IFERROR(VLOOKUP(SMALL($I$2:$I$35,G9),$G$2:$H$35,2,FALSE),"X") -> Licda. Helen Massiel Martinez | M9: desref (j2;0;;contar.si(listado;<>0))
A10: LABORATORIO CLINICO | B10: 538A08 | C10: Merlin Aparicio | D10: Licda. Kathy Portillo | G10: 9 | H10: =C10 -> Merlin Aparicio | I10: =IF(H10=0,MAX($G$2:$G$35)+1,G10) -> 9 | J10: =IFERROR(VLOOKUP(SMALL($I$2:$I$35,G10),$G$2:$H$35,2,FALSE),"X") -> Xiomara Alberto
A11: MEDICINA FISICA Y REHABILITACION | B11: 538A22 | C11: Licda. Helen Massiel Martinez | D11: Licda. Helen Massiel Martinez | G11: 10 | H11: =C11 -> Licda. Helen Massiel Martinez | I11: =IF(H11=0,MAX($G$2:$G$35)+1,G11) -> 10 | J11: =IFERROR(VLOOKUP(SMALL($I$2:$I$35,G11),$G$2:$H$35,2,FALSE),"X") -> Ing. Yohana Laug
A12: NUTRICION (DIETOLOGIA CLINICA) | B12: 538A24 | C12: Xiomara Alberto | G12: 11 | H12: =C12 -> Xiomara Alberto | I12: =IF(H12=0,MAX($G$2:$G$35)+1,G12) -> 11 | J12: =IFERROR(VLOOKUP(SMALL($I$2:$I$35,G12),$G$2:$H$35,2,FALSE),"X") -> Licdo. Daniel Hernandez
A13: EDUCACION PARA LA SALUD | B13: 538A26 | C13: Ing. Yohana Laug | G13: 12 | H13: =C13 -> Ing. Yohana Laug | I13: =IF(H13=0,MAX($G$2:$G$35)+1,G13) -> 12 | J13: =IFERROR(VLOOKUP(SMALL($I$2:$I$35,G13),$G$2:$H$35,2,FALSE),"X") -> Licda. Yolanda Oporto
A14: TERAPIA RESPIRATORIA | B14: 538A31 | C14: Licdo. Daniel Hernandez | G14: 13 | H14: =C14 -> Licdo. Daniel Hernandez | I14: =IF(H14=0,MAX($G$2:$G$35)+1,G14) -> 13 | J14: =IFERROR(VLOOKUP(SMALL($I$2:$I$35,G14),$G$2:$H$35,2,FALSE),"X") -> Dania Mejia | M14: =OFFSET(J2,0,,COUNTIF(listado,"<>x")) -> Dania Mejia
A15: SALUD MENTAL | B15: 538A38 | C15: Licda. Yolanda Oporto | D15: Licda. Sandra Calles | G15: 14 | H15: =C15 -> Licda. Yolanda Oporto | I15: =IF(H15=0,MAX($G$2:$G$35)+1,G15) -> 14 | J15: =IFERROR(VLOOKUP(SMALL($I$2:$I$35,G15),$G$2:$H$35,2,FALSE),"X") -> Claudia Perez
A16: ATENCION PALIATIVA | B16: 538A45 | G16: 15 | H16: =C16 -> 0 | I16: =IF(H16=0,MAX($G$2:$G$35)+1,G16) -> 35 | J16: =IFERROR(VLOOKUP(SMALL($I$2:$I$35,G16),$G$2:$H$35,2,FALSE),"X") -> Debora Escobar
A17: CENTRAL DE ESTERILIZACION Y SUMINISTROS | B17: 538B01 | C17: Dania Mejia | G17: 16 | H17: =C17 -> Dania Mejia | I17: =IF(H17=0,MAX($G$2:$G$35)+1,G17) -> 16 | J17: =IFERROR(VLOOKUP(SMALL($I$2:$I$35,G17),$G$2:$H$35,2,FALSE),"X") -> Claudia Iris Torrento
A18: ENFERMERIA | B18: 538B02 | C18: Claudia Perez | G18: 17 | H18: =C18 -> Claudia Perez | I18: =IF(H18=0,MAX($G$2:$G$35)+1,G18) -> 17 | J18: =IFERROR(VLOOKUP(SMALL($I$2:$I$35,G18),$G$2:$H$35,2,FALSE),"X") -> Licda. Lino
A19: FARMACIA | B19: 538B03 | C19: Debora Escobar | D19: Lica. Maria Elsa | G19: 18 | H19: =C19 -> Debora Escobar | I19: =IF(H19=0,MAX($G$2:$G$35)+1,G19) -> 18 | J19: =IFERROR(VLOOKUP(SMALL($I$2:$I$35,G19),$G$2:$H$35,2,FALSE),"X") -> Licda. Mercedes Hidalgo
A20: TRABAJO SOCIAL | B20: 538B04 | C20: Claudia Iris Torrento | G20: 19 | H20: =C20 -> Claudia Iris Torrento | I20: =IF(H20=0,MAX($G$2:$G$35)+1,G20) -> 19 | J20: =IFERROR(VLOOKUP(SMALL($I$2:$I$35,G20),$G$2:$H$35,2,FALSE),"X") -> Celina Martínez
A21: MEDICINA INTERNA | B21: 538202 | G21: 20 | H21: =C21 -> 0 | I21: =IF(H21=0,MAX($G$2:$G$35)+1,G21) -> 35 | J21: =IFERROR(VLOOKUP(SMALL($I$2:$I$35,G21),$G$2:$H$35,2,FALSE),"X") -> Licda. Mayra Acosta
A22: DEMATOLOGIA | B22: 538213 | G22: 21 | H22: =C22 -> 0 | I22: =IF(H22=0,MAX($G$2:$G$35)+1,G22) -> 35 | J22: =IFERROR(VLOOKUP(SMALL($I$2:$I$35,G22),$G$2:$H$35,2,FALSE),"X") -> Licda. Iris Vivas
A23: MEDICINA GENERAL | B23: 538214 | C23: Licda. Lino | G23: 22 | H23: =C23 -> Licda. Lino | I23: =IF(H23=0,MAX($G$2:$G$35)+1,G23) -> 22 | J23: =IFERROR(VLOOKUP(SMALL($I$2:$I$35,G23),$G$2:$H$35,2,FALSE),"X") -> Silvia Flamenco
A24: EMERGENCIA, MEDICINA Y CIRUGIA | B24: 538217 | C24: Licda. Mercedes Hidalgo | G24: 23 | H24: =C24 -> Licda. Mercedes Hidalgo | I24: =IF(H24=0,MAX($G$2:$G$35)+1,G24) -> 23 | J24: =IFERROR(VLOOKUP(SMALL($I$2:$I$35,G24),$G$2:$H$35,2,FALSE),"X") -> Karla Menjivar
A25: EMERGENCIA PEDIATRICA | B25: 538504 | G25: 24 | H25: =C25 -> 0 | I25: =IF(H25=0,MAX($G$2:$G$35)+1,G25) -> 35 | J25: =IFERROR(VLOOKUP(SMALL($I$2:$I$35,G25),$G$2:$H$35,2,FALSE),"X") -> Dra. Hernandez
A26: CIRUGIA GENERAL | B26: 538304 | C26: Celina Martínez | G26: 25 | H26: =C26 -> Celina Martínez | I26: =IF(H26=0,MAX($G$2:$G$35)+1,G26) -> 25 | J26: =IFERROR(VLOOKUP(SMALL($I$2:$I$35,G26),$G$2:$H$35,2,FALSE),"X") -> Licdo. Geovvani Torres
A27: OFTALMOLOGIA | B27: 538307 | G27: 26 | H27: =C27 -> 0 | I27: =IF(H27=0,MAX($G$2:$G$35)+1,G27) -> 35 | J27: =IFERROR(VLOOKUP(SMALL($I$2:$I$35,G27),$G$2:$H$35,2,FALSE),"X") -> X
A28: OTORRINOLARINGOLOGIA | B28: 538308 | G28: 27 | H28: =C28 -> 0 | I28: =IF(H28=0,MAX($G$2:$G$35)+1,G28) -> 35 | J28: =IFERROR(VLOOKUP(SMALL($I$2:$I$35,G28),$G$2:$H$35,2,FALSE),"X") -> X
A29: GINECOLOGIA Y OBSTETRICIA | B29: 538402 | C29: Licda. Mayra Acosta | G29: 28 | H29: =C29 -> Licda. Mayra Acosta | I29: =IF(H29=0,MAX($G$2:$G$35)+1,G29) -> 28 | J29: =IFERROR(VLOOKUP(SMALL($I$2:$I$35,G29),$G$2:$H$35,2,FALSE),"X") -> X
A30: PEDIATRIA | B30: 538502 | C30: Licda. Iris Vivas | G30: 29 | H30: =C30 -> Licda. Iris Vivas | I30: =IF(H30=0,MAX($G$2:$G$35)+1,G30) -> 29 | J30: =IFERROR(VLOOKUP(SMALL($I$2:$I$35,G30),$G$2:$H$35,2,FALSE),"X") -> X
A31: ODONTOLOGIA GENERAL | B31: 538702 | C31: Silvia Flamenco | D31: Dra. Blanca Fuentes de Vent. | G31: 30 | H31: =C31 -> Silvia Flamenco | I31: =IF(H31=0,MAX($G$2:$G$35)+1,G31) -> 30 | J31: =IFERROR(VLOOKUP(SMALL($I$2:$I$35,G31),$G$2:$H$35,2,FALSE),"X") -> X
A32: CLINICA COMUNAL REPATO MORAZAN | B32: 538C01 | C32: Karla Menjivar | D32: Dra. Doris Acosta | G32: 31 | H32: =C32 -> Karla Menjivar | I32: =IF(H32=0,MAX($G$2:$G$35)+1,G32) -> 31 | J32: =IFERROR(VLOOKUP(SMALL($I$2:$I$35,G32),$G$2:$H$35,2,FALSE),"X") -> X
A33: PROYECTO ATENCION CONSULTA EXTERNA NIÑOS, CLINICA COMUNAL REPARTO MORAZAN | B33: 538CX4 | G33: 32 | H33: =C33 -> 0 | I33: =IF(H33=0,MAX($G$2:$G$35)+1,G33) -> 35 | J33: =IFERROR(VLOOKUP(SMALL($I$2:$I$35,G33),$G$2:$H$35,2,FALSE),"X") -> X
A34: CLINICA COMUNAL SAN JOSE | B34: 538C02 | C34: Dra. Hernandez | D34: Dr- Angel Cortez | G34: 33 | H34: =C34 -> Dra. Hernandez | I34: =IF(H34=0,MAX($G$2:$G$35)+1,G34) -> 33 | J34: =IFERROR(VLOOKUP(SMALL($I$2:$I$35,G34),$G$2:$H$35,2,FALSE),"X") -> X
A35: HOSPITALIZACIÓN PEDIÁTRICA | B35: 538506 | C35: Licdo. Geovvani Torres | G35: 34 | H35: =C35 -> Licdo. Geovvani Torres | I35: =IF(H35=0,MAX($G$2:$G$35)+1,G35) -> 34 | J35: =IFERROR(VLOOKUP(SMALL($I$2:$I$35,G35),$G$2:$H$35,2,FALSE),"X") -> X
A36: Otros

Sheet BaseMateriales
A1: Codigo | B1: DESCRIPICION | C1: Codigo Antiguo | D1: Estatus Mat | E1: Unidad Medida | F1: Descripcion EstatusMaterial | G1: Precio | H1: Planificado2025 | I1: Planificado2026
A2: 100100001 | B2: MARCAPASO DESFIBRILADOR CARDIOVERTER, BICAMERAL, IMPLANTABLE, PROGRAMADO CON SISTEMA DE MONITOREO INTRACARDIACO, QUE INCLUYA CABLE AURICULARY VENTRICULAR DE FIJACIÓN ACTIVO Y UNA O DOS BOBINAS | C2: 7015093 | E2: UN | H2: 11500 | I2: NO PLANIFICADO
A3: 100100002 | B3: MARCAPASO DOBLE CÁMARA MULTIPROGRAMABLE CON SU ELECTRODO ENDOCARDICO AURICULAR Y VENTRICULAR. | C3: 7015094 | E3: UN | H3: 0 | I3: NO PLANIFICADO
A4: 100100003 | B4: MARCAPASO VVIR MULTIPROGRAMABLE CON SU ELECTRODO ENDOCÁRDICO. | C4: 7015097 | E4: UN | H4: 875 | I4: NO PLANIFICADO
A5: 100100004 | B5: NEURO-ESTIMULADOR MEDULAR IMPLANTABLE (GENERADOR DEFINITIVO) DE 8 CONTACTOS, QUE INCLUYA ELECTRODO PERCUTÁNEO Y ASISTENCIA TÉCNICA DURANTE LA COLOCACIÓN EN PACIENTE | C5: 7015098 | E5: UN | H5: 17029.1 | I5: 20
A6: 100100005 | B6: ELECTRODO IMPLANTABLE TRIAL DE 8 CONTACTOS PARA COLOCACIÓN VÍA PERCUTÁNEA ENTRE EL RANGO DE 45 CM A 75 CM, COMPATIBLE CON RESONANCIA MAGNÉTICA Y NEUROESTIMULADOR IMPLANTADO. | E6: UN | H6: 0 | I6: NO PLANIFICADO
A7: 100100006 | B7: CONFORMADOR PERFORADO MEDIANO PARA OCULOPLASTIA | E7: UN | H7: 0 | I7: NO PLANIFICADO
A8: 100100007 | B8: CONFORMADOR PERFORADO PEQUEÑO PARA OCULOPLASTIA | E8: UN | H8: 0 | I8: NO PLANIFICADO
A9: 100100008 | B9: IMPLANTE ORBITARIO DE 22 MM PARA OCULOPLASTIA | E9: UN | H9: 0 | I9: NO PLANIFICADO
A10: 100100009 | B10: IMPLANTE ORBITARIO DE 20 MM PARA OCULOPLASTIA | E10: UN | H10: 0 | I10: NO PLANIFICADO
A11: 100100010 | B11: IMPLANTE ORBITARIO DE 18 MM PARA OCULOPLASTIA | E11: UN | H11: 0 | I11: NO PLANIFICADO
A12: 100100011 | B12: IMPLANTE ORBITARIO DE 16 MM PARA OCULOPLASTIA | E12: UN | H12: 0 | I12: NO PLANIFICADO
A13: 100100015 | B13: CONFORMADOR PERFORADO GRANDE PARA OCULOPLASTIA | E13: UN | H13: 0 | I13: NO PLANIFICADO
A14: 100200001 | B14: CARTUCHO PARA ANÁLISIS DE QUÍMICA POR MICROMUESTRA (65 - 95 MICROLITROS) | C14: 7015071 | E14: UN | H14: 15.89 | I14: 0
A15: 100200002 | B15: CARTUCHO PARA ANÁLISIS DE QUÍMICA SANGUÍNEA POR MICRO MUESTRA QUE INCLUYA MEDICIÓN DE GASES ARTERIALES SANGUÍNEOS | C15: 7015127 | D15: FUERA DE LISTADO OFICIAL | E15: UN | F15: FUERA DE LISTADO OFICIAL | H15: 14.84 | I15: 750
A16: 100200003 | B16: CONECTOR PARA CATÉTER DE HEMODIÁLISIS, BIOCOMPATIBLE, SISTEMA PARA USOSIN AGUJA, CON CIERRE MICROBIOLÓGICO | C16: 7035014 | E16: UN | H16: 6.99 | I16: 5800
A17: 100200004 | B17: CATÉTER DOBLE LUMEN PARA HEMODIÁLISIS, DE 11 A 12 FRENCH, DE 15 A 16 CM DE LONGITUD, CON EXTENSIÓN CURVA, INCLUYE: GUÍA METÁLICA CON EXTREMOEN "J", AGUJA INTRODUCTORA, DILATADOR Y DOS TAPONES | C17: 7035023 | E17: UN | H17: 34.94 | I17: 160
A18: 100200005 | B18: CATÉTER DOBLE LUMEN PARA HEMODIÁLISIS, DE 11.5 A 12 FRENCH, DE 18 A 20CM DE LONGITUD, CON EXTENSIÓN LARGA, INCLUYE: GUÍA METÁLICA CON EXTREMO EN "J", AGUJA INTRODUCTORA, DILATADOR Y DOS TAPONES. | C18: 7035024 | E18: UN | H18: 40 | I18: 60
A19: 100200006 | B19: KIT PARA COLOCACIÓN PERCUTÁNEA DE CATÉTER BLANDO, QUE CONTENGA: CATÉTER BLANDO DE 56 - 65 CM DE LONGITUD TOTAL, EXTREMO EN ESPIRAL, CON DOBLE COJINETE, ADAPTADOR O CONECTOR CIRCULAR A LÍNEA DE TRANSFERENCIA, CAMISA/DILATADOR DE 16 FRENCH, GUÍA METÁLICA CON EXTREMO EN "J", AGUJA INTRODUCTORA DE 18 GA Y ESTILETE TUNELIZADOR | C19: 7035030 | E19: UN | H19: 93.63 | I19: 190
A20: 100200007 | B20: FILTRO DE HEMOADSORCIÓN PARA TRATAR DESEQUILIBRIO INFLAMATORIO PORRESPUESTA INMUNE EXCESIVA, ELABORADO CON COPOLÍMEROS, CAPACIDAD SANGUÍNEAEXTRACORPÓREA DE 95 - 200 ML, BAJA RESISTENCIA AL FLUJO, LIBRE DE LÁTEX, FTALATOS Y PIRÓGENOS, INCLUYE SET DE CONEXIÓN ESTÉRIL CON ACCESORIOS NECESARIOS PARA LA CORRECTA APLICACIÓN DE LA TERAPIA. | C20: 7035039 | E20: UN | H20: 320 | I20: 120
A21: 100200008 | B21: FILTRO PARA HEMOPERFUSIÓN O HEMOADSORCIÓN PARA TRATAR ENVENENAMIENTO OSOBREDOSIS DE DROGAS, ELABORADO CON COPOLÍMEROS, CAPACIDAD SANGUÍNEAEXTRACORPÓREA DE 95 - 200 ML, BAJA RESISTENCIA AL FLUJO, LIBRE DE LÁTEX, FTALATOS Y PIRÓGENOS, INCLUYE SET DE CONEXIÓN ESTÉRIL CON ACCESORIOS NECESARIOS PARA LA CORRECTA APLICACIÓN DE LA TERAPIA. | C21: 7035040 | E21: UN | H21: 275 | I21: 36
A22: 100200009 | B22: FILTRO DE HEMOPERFUSIÓN O HEMOADSORCIÓN PARA TRATAR ENFERMEDAD RENAL CRÓNICA, PARA REMOVER TOXINAS URÉMICAS UNIDAS A PROTEÍNAS, ELABORADO CON COPOLÍMEROS, CONTENIDO DE ADSORBENTE ENTRE 130 - 300 ML, CAPACIDAD SANGUÍNEA EXTRACORPÓREA DE 95 - 200 ML, BAJA RESISTENCIA AL FLUJO, LIBRE DE LÁTEX, FTALATOS Y PIRÓGENOS, INCLUYE UN SET DE CONEXIÓN ESTÉRIL CON ACCESORIOS NECESARIOS PARA LA CORRECTA APLICACIÓN DE LA TERAPIA | C22: 7035041 | E22: UN | H22: 1800 | I22: 180
A23: 100200010 | B23: KIT DE TIRA REACTIVA Y LANCETA PARA DETERMINAR GLUCOSA EN SANGRE EN UNIDAD DE MEDIDA MG/DL | C23: 7054133 | E23: UN | H23: 0.26 | I23: 700
A24: 100200011 | B24: FILTRO PARA HEMOADSORCIÓN PARA TRATAR DESEQUILIBRIO INFLAMATORIO POR RESPUESTA INMUNE EXCESIVA. ELABORADO CON POLÍMERO RETICULADO CON DIVINILBENCENO, CONTENIDO DE ADSORBENTE DE 300 ML O MÁS, CAPACIDAD SANGUÍNEAEXTRACORPÓREA DE 140-150 ML, BAJA RESISTENCIA AL FLUJO, LIBRE DE LÁTEX, FTALATOS Y PIRÓGENOS, DESCARTABLE, ESTÉRIL | C24: 7054142 | E24: UN | H24: 2020.06 | I24: 80
A25: 100200012 | B25: CAMPANA PARA RECUPERADOR CELULAR DE 125 A 140 ML, COMPATIBLE CON EQUIPO | C25: 7080148 | E25: UN | H25: 349 | I25: 50
A26: 100200013 | B26: CONO PARA CENTRÍFUGA, TAMAÑO ADULTO, PARA BOMBA DE CIRCULACIÓN EXTRACORPÓREA. | C26: 7080188 | E26: UN | H26: 582 | I26: 156
A27: 100200014 | B27: SET PARA ADMINISTRACIÓN DE CARDIOPLEJÍA SANGUÍNEA | C27: 7080207 | E27: UN | H27: 0 | I27: NO PLANIFICADO
A28: 100200015 | B28: SISTEMA DE MEMBRANA PARA CIRCULACIÓN EXTRACORPÓREA, ADULTO, CONSTA DE:1 OXIGENADOR DE MEMBRANA CON FILTRO ARTERIAL INTEGRADO, FILTRO DE OXÍGENO, CON SET DE TUBERÍAS SEGÚN DIAGRAMA, HEMOCONCENTRADOR SIN PARAFINA CON LÍNEA DE 1/4", SET PARA ADMINISTRACIÓN DE CARDIOPLEJIA SANGUÍNEA | C28: 7080208 | E28: UN | H28: 945 | I28: 156
A29: 100200016 | B29: TRANSDUCTOR Y CONO PARA CENTRÍFUGA, TAMAÑO ADULTO, PARA BOMBA DE CIRCULACIÓN EXTRACORPÓREA | C29: 7080210 | E29: UN | H29: 0 | I29: NO PLANIFICADO
A30: 100300001 | B30: AGUJA CARPULE CORTA # 27 G, DE 21 MM. DESCARTABLE | C30: 4005072 | E30: UN | H30: 0.09 | I30: 2
A31: 100300002 | B31: AGUJA CARPULE CORTA # 30 G, DE 21 MM. DESCARTABLE | C31: 4005073 | E31: UN | H31: 0.08 | I31: 4
A32: 100300003 | B32: AGUJA CARPULE LARGA # 27 G, DE 30 A 32 MM. DESCARTABLE | C32: 4005074 | E32: UN | H32: 0.08 | I32: 1
A33: 100300004 | B33: AGUJA CARPULE EXTRA CORTA # 30 G, DE 10 A 12 MM, DESCARTABLE | C33: 4006000 | E33: UN | H33: 0.121 | I33: 200
A34: 100300005 | B34: JERINGA CARPULE | C34: 4201056 | E34: UN | H34: 10.3 | I34: 6
A35: 100300006 | B35: AGUJA PARA PUNCIÓN ESPINAL, PUNTA TIPO WHITACRE, 25 G, ENTRE 4 1/4" A5" DE LONGITUD, ESTÉRIL, DESCARTABLE, INCLUYE SU RESPECTIVO INTRODUCTOR | C35: 7010041 | E35: UN | H35: 0 | I35: NO PLANIFICADO
A36: 100300007 | B36: AGUJA PARA ANESTESIA DE PLEXO DE 0.55 MM 24G X 1", DESCARTABLE. | C36: 7010117 | E36: UN | H36: 18 | I36: 41
A37: 100300008 | B37: AGUJA PARA MÉDULA ÓSEA 16G, LONGITUD DE 1 A 2", COMPATIBLE CON CONECTOR LUER SLIP O LUER LOCK, DESCARTABLE. | C37: 7010118 | E37: UN | H37: 42 | I37: 36
A38: 100300009 | B38: AGUJA PARA ANESTESIA DE PLEXO DE 22 G X 2" DE LONGITUD, CON CABLE PARANEUROESTIMULADOR, PARA SER VISUALIZADO POR ULTRASONIDO, DESCARTABLE | C38: 7010122 | E38: UN | H38: 30 | I38: 50
A39: 100300010 | B39: AGUJA PARA ANESTESIA DE PLEXO DE 20 G X 6" DE LONGITUD, CON CABLE PARANEUROESTIMULADOR, PARA SER VISUALIZADO POR ULTRASONIDO, DESCARTABLE. | C39: 7010123 | E39: UN | H39: 6 | I39: 45
A40: 100300011 | B40: AGUJA PARA PUNCIÓN DE MÉDULA ÓSEA 11 G, 4" DE LONGITUD, CON MANDRIL,ESTÉRIL, DESCARTABLE | C40: 7010132 | E40: UN | H40: 50 | I40: 428
...
